<?xml version='1.0'?>
<robot xmlns:xacro="http://www.ros.org/wiki/xacro" name="AGV">
<xacro:property name="ns" value="$(arg ns)/" />
  <link name="${ns}base_link">
    <visual>
      <origin xyz="0 0 0" rpy="0 0 1.5709" />
      <geometry>
        <mesh filename="package://data/meshes/agv_base.DAE" scale="0.5 0.5 0.5" />
      </geometry>
      <material name="white">
        <color rgba="1 0.29804 0.0 1" />
      </material>
    </visual>
  </link>

  <!--front axle-->
  <link name="${ns}front_axle">
    <visual>
      <origin xyz="0 0 0" rpy="0 0 1.5709" />
      <geometry>
        <mesh filename="package://data/meshes/agv_axle.DAE" scale="0.5 0.5 0.5" />
      </geometry>
      <material name="">
        <color rgba="1 0.29804 0.0 1" />
      </material> 
    </visual>
  </link>
  <joint name="${ns}base_to_front_axle_steering_shaft" type="continuous">
    <origin rpy="0  0  0" xyz="2.5  0 0.35"/>
    <parent link="${ns}base_link"/>
    <child link="${ns}front_axle"/>    
    <axis xyz="0 0 1"/>
  </joint>
    <!--    front wheel                        -->
    <link name="${ns}front_wheel">
    <visual>
      <origin xyz="0 0 0" rpy="0 0 1.5709" />
      <geometry>
        <mesh filename="package://data/meshes/agv_wheel.DAE" scale="0.5 0.5 0.5"/>
      </geometry>
      <material name="">
        <color rgba="0.29804 0.29804 0.29804 1" />
      </material>
    </visual>
  </link>
  <joint name="${ns}front_axle_to_front_wheel" type="fixed">
    <origin xyz="0 0.0 0.0" rpy="0 0 0" />
    <parent link="${ns}front_axle" />
    <child link="${ns}front_wheel" />
    <axis xyz="0 1 0" />
  </joint>

    <!--back axle-->
  <link name="${ns}back_axle">
    <visual>
      <origin xyz="0 0 0" rpy="0 0 1.5709" />
      <geometry>
        <mesh filename="package://data/meshes/agv_axle.DAE" scale="0.5 0.5 0.5" />
      </geometry>
      <material name="">
        <color rgba="1 0.29804 0.0 1" />
      </material> 
    </visual>
  </link>
  <joint name="${ns}base_to_back_axle_steering_shaft" type="fixed">
    <origin rpy="0  0  0" xyz="-2.5  0  0.35"/>
    <parent link="${ns}base_link"/>
    <child link="${ns}back_axle"/>    
    <axis xyz="0 0 1"/>
  </joint>
    <!--    back wheel                        -->
    <link name="${ns}back_wheel">
    <visual>
      <origin xyz="0 0 0" rpy="0 0 1.5709" />
      <geometry>
        <mesh filename="package://data/meshes/agv_wheel.DAE" scale="0.5 0.5 0.5"/>
      </geometry>
      <material name="">
        <color rgba="0.29804 0.29804 0.29804 1" />
      </material>
    </visual>
  </link>
  <joint name="${ns}back_axle_to_back_wheel" type="fixed">
    <origin xyz="0 0.0 0.0" rpy="0 0 0" />
    <parent link="${ns}back_axle" />
    <child link="${ns}back_wheel" />
    <axis xyz="0 1 0" />
  </joint>

      <link name="${ns}logo_link">
    <visual>
      <geometry>
        <box size="0.8 0.15 0.01"/>
      </geometry>
      <material name="">
         <color rgba="1 1 1 .5"/>
         <texture filename="package://data/meshes/superg-ai.jpg"/>
    </material>
    </visual>
  </link>
  <joint name="${ns}base_to_logo_link" type="fixed">
    <origin xyz="0  0.16  0.3" rpy="-1.57075  0  0"/>
    <parent link="${ns}base_link"/>
    <child link="${ns}logo_link"/>
  </joint>

    <link name="${ns}logo_link2">
    <visual>
      <geometry>
        <box size="0.8 0.15 0.01"/>
      </geometry>
      <material name="">
         <color rgba="1 1 1 .5"/>
         <texture filename="package://data/meshes/superg-ai.jpg"/>
    </material>
    </visual>
  </link>
  <joint name="${ns}base_to_logo_link2" type="fixed">
    <origin xyz="0  -0.16 0.3" rpy="1.57075  3.14  0"/>
    <parent link="${ns}base_link"/>
    <child link="${ns}logo_link2"/>
  </joint>
</robot>
